Workbook
Name Metal: #REF!
Name Pop: #REF!
Name Jazz: #REF!
Name Electronic: #REF!
Name Classical: #REF!
Name International: #REF!
Name Hip_Hop: #REF!
Name R_B: #REF!
Name Rap: #REF!
Name Parent_Genre: #REF!
Name Other: #REF!
Name Rock: #REF!
Name Country: #REF!

Sheet Da Rules
A1: The Constitution of Music Book Club
A5: Bill of Rights | G5: Rules
A6: 1 | B6: Right to vote | G6: 1 | H6: The user shall post a song every Mon, Wed, Fri
A7: 2 | B7: Right to post any song | G7: 2 | H7: The user shall listen to each song until the song ends or for at least 6 minutes, whichever comes first
A8: 3 | G8: 3 | H8: The user shall be truthful with the votes
A9: 4 | G9: 4 | H9: The user shall not repeat a song
A10: 5 | G10: 5 | H10: Non-Proliferation Treaty
A11: 6 | G11: 6
A12: 7 | G12: 7
A13: 8 | G13: 8
A14: 9 | G14: 9
A15: 10 | G15: 10
A16: Rosey Faces | G16: Proposed Rules | M16: Logan | N16: Parker | O16: Giacomo | P16: Rosey | Q16: TTAC | R16: Weston | S16: Jake
A17: 1 | G17: 1 | H17: Lil TJay is banished to the shadow realm | M17: Y | N17: faggot | O17: W | R17: ?
A18: 2 | G18: 2 | H18: No Tinkering of Votes | M18: Y | N18: fag | O18: Tink By Smino | R18: 1 | S18: 🚁
A19: 3 | G19: 3 | H19: Amendment's only need 6/7 votes to pass :) | M19: Y | N19: fag | O19: 😡 | R19: 1 | S19: 🚁
A20: 4 | G20: 4 | H20: TTAC Daily 7 | N20: fag | P20: O/ | | R20: 1 | S20: 🛶
A21: 5 | G21: 5 | H21: Removal of all photos/gifs | O21: Inshallah | R21: 1 | S21: 🚁
A22: 6 | G22: 6 | H22: add flocco | O22: 🦉 | R22: 1
A23: 7 | G23: 7
A24: 8 | G24: 8
A25: 9 | G25: 9
A26: 10 | G26: 10
A27: 11 | G27: 11
A28: 12 | G28: 12
A29: 13 | G29: 13
A30: 14 | G30: 14
A31: 15 | G31: 15
G32: If rules have been proposed, votes will be cast in this document. If the rule was proposed before noon, a vote will be held and a ruling will be made by the end of the same work day. Otherwise, a vote and ruling will be held the following work day. A unanimous vote is needed to pass.

Sheet Rankings
A1: Date | B1: Album Art | C1: Winner of the day | D1: Date | E1: Poster | F1: Average | G1: STDEV | H1: Peer Rank | I1: Song Title | J1: Artist | K1: Logan | L1: Parker | M1: Giacomo | N1: Rosey | O1: TTAC | P1: Weston | Q1: Flocco | R1: Jake | S1: Day Rank | T1: W Rank | U1: Winner | V1: Score | W1: Notes
A2: 45908 | C2: {=INDEX(Rankings!$E$2:$E$8, MATCH(1, (Rankings!$D$2:$D$8=A2)*(Rankings!$U$2:$U$8=TRUE()), 0))} -> Parker | D2: =A2 -> 45908 | E2: =$K$1 -> Logan | F2: =IFERROR(AVERAGE(Rankings!$K2:$R2), "TBD") -> 4.4285714 | G2: =IFERROR(_xlfn.STDEV.P(Rankings!$K2:$R2), "TBD") -> 2.1285235 | H2: =IFERROR(AVERAGE(Rankings!$L2:$R2), "TBD") -> 4.8333333 | I2: Earthquake | J2: Ferdous | K2: 2 | L2: 7 | M2: 7 | N2: 5 | O2: 5 | P2: 4 | R2: 1 | S2: =IF(SUM(Rankings!$K2:$R2)>0, COUNTIFS(Rankings!$D$2:$D$987, Rankings!$D2, Rankings!$F$2:$F$987, "<"&Rankings!$F2) + COUNTIFS(Rankings!$D$2:$D$987, Rankings!$D2, Rankings!$F$2:$F$987, Rankings!$F2, Rankings!$G$2:$G$987, "<"&Rankings!$G2)+1, "TBD") -> 5 | T2: 1 | U2: =Rankings!$S2=Rankings!$T2 -> FALSE
D3: =D2 -> 45908 | E3: =$L$1 -> Parker | F3: =IFERROR(AVERAGE(Rankings!$K3:$R3), "TBD") -> 2.1428571 | G3: =IFERROR(_xlfn.STDEV.P(Rankings!$K3:$R3), "TBD") -> 0.63887657 | H3: =IFERROR(AVERAGE(Rankings!$K3, Rankings!$M3:$R3), "TBD") -> 2.1666667 | I3: Send it Back | J3: Don West | K3: 3 | L3: 2 | M3: 2 | N3: 3 | O3: 2 | P3: 1 | R3: 2 | S3: =IF(SUM(Rankings!$K3:$R3)>0, COUNTIFS(Rankings!$D$2:$D$987, Rankings!$D3, Rankings!$F$2:$F$987, "<"&Rankings!$F3) + COUNTIFS(Rankings!$D$2:$D$987, Rankings!$D3, Rankings!$F$2:$F$987, Rankings!$F3, Rankings!$G$2:$G$987, "<"&Rankings!$G3)+1, "TBD") -> 1 | T3: 1 | U3: =Rankings!$S3=Rankings!$T3 -> TRUE
D4: =D2 -> 45908 | E4: =$M$1 -> Giacomo | F4: =IFERROR(AVERAGE(Rankings!$K4:$R4), "TBD") -> 4.1428571 | G4: =IFERROR(_xlfn.STDEV.P(Rankings!$K4:$R4), "TBD") -> 1.9587585 | H4: =IFERROR(AVERAGE(Rankings!$K4:$L4, Rankings!$N4:$R4), "TBD") -> 4.6666667 | I4: FOCUS | J4: _BY.ALEXANDER | K4: 4 | L4: 4 | M4: 1 | N4: 2 | O4: 7 | P4: 5 | R4: 6 | S4: =IF(SUM(Rankings!$K4:$R4)>0, COUNTIFS(Rankings!$D$2:$D$987, Rankings!$D4, Rankings!$F$2:$F$987, "<"&Rankings!$F4) + COUNTIFS(Rankings!$D$2:$D$987, Rankings!$D4, Rankings!$F$2:$F$987, Rankings!$F4, Rankings!$G$2:$G$987, "<"&Rankings!$G4)+1, "TBD") -> 3 | T4: 1 | U4: =Rankings!$S4=Rankings!$T4 -> FALSE
D5: =D2 -> 45908 | E5: =$N$1 -> Rosey | F5: =IFERROR(AVERAGE(Rankings!$K5:$R5), "TBD") -> 4.8571429 | G5: =IFERROR(_xlfn.STDEV.P(Rankings!$K5:$R5), "TBD") -> 1.8070158 | H5: =IFERROR(AVERAGE(Rankings!$K5:$M5, Rankings!$O5:$R5), "TBD") -> 5.5 | I5: Aloe Lite | J5: Good Kid | K5: 5 | L5: 6 | M5: 6 | N5: 1 | O5: 4 | P5: 7 | R5: 5 | S5: =IF(SUM(Rankings!$K5:$R5)>0, COUNTIFS(Rankings!$D$2:$D$987, Rankings!$D5, Rankings!$F$2:$F$987, "<"&Rankings!$F5) + COUNTIFS(Rankings!$D$2:$D$987, Rankings!$D5, Rankings!$F$2:$F$987, Rankings!$F5, Rankings!$G$2:$G$987, "<"&Rankings!$G5)+1, "TBD") -> 6 | T5: 1 | U5: =Rankings!$S5=Rankings!$T5 -> FALSE
D6: =D2 -> 45908 | E6: =$O$1 -> TTAC | F6: =IFERROR(AVERAGE(Rankings!$K6:$R6), "TBD") -> 5 | G6: =IFERROR(_xlfn.STDEV.P(Rankings!$K6:$R6), "TBD") -> 2.0701967 | H6: =IFERROR(AVERAGE(Rankings!$K6:$N6, Rankings!$P6:$R6), "TBD") -> 5.6666667 | I6: Buttercup | J6: Hippo Campus | K6: 7 | L6: 5 | M6: 3 | N6: 6 | O6: 1 | P6: 6 | R6: 7 | S6: =IF(SUM(Rankings!$K6:$R6)>0, COUNTIFS(Rankings!$D$2:$D$987, Rankings!$D6, Rankings!$F$2:$F$987, "<"&Rankings!$F6) + COUNTIFS(Rankings!$D$2:$D$987, Rankings!$D6, Rankings!$F$2:$F$987, Rankings!$F6, Rankings!$G$2:$G$987, "<"&Rankings!$G6)+1, "TBD") -> 7 | T6: 1 | U6: =Rankings!$S6=Rankings!$T6 -> FALSE
D7: =D3 -> 45908 | E7: =$P$1 -> Weston | F7: =IFERROR(AVERAGE(Rankings!$K7:$R7), "TBD") -> 3.1428571 | G7: =IFERROR(_xlfn.STDEV.P(Rankings!$K7:$R7), "TBD") -> 1.7261494 | H7: =IFERROR(AVERAGE(Rankings!$K7:$O7, Rankings!$R7), "TBD") -> 3.3333333 | I7: Snap my Finger | J7: Kaytranada | K7: 1 | L7: 1 | M7: 4 | N7: 4 | O7: 6 | P7: 2 | R7: 4 | S7: =IF(SUM(Rankings!$K7:$R7)>0, COUNTIFS(Rankings!$D$2:$D$987, Rankings!$D7, Rankings!$F$2:$F$987, "<"&Rankings!$F7) + COUNTIFS(Rankings!$D$2:$D$987, Rankings!$D7, Rankings!$F$2:$F$987, Rankings!$F7, Rankings!$G$2:$G$987, "<"&Rankings!$G7)+1, "TBD") -> 2 | T7: 1 | U7: =Rankings!$S7=Rankings!$T7 -> FALSE
D8: =D4 -> 45908 | E8: =$R$1 -> Jake | F8: =IFERROR(AVERAGE(Rankings!$K8:$R8), "TBD") -> 4.2857143 | G8: =IFERROR(_xlfn.STDEV.P(Rankings!$K8:$R8), "TBD") -> 1.5779087 | H8: =IFERROR(AVERAGE(Rankings!$K8:$P8), "TBD") -> 4.5 | I8: Help Is On It's Way | J8: Little River Band | K8: 6 | L8: 3 | M8: 5 | N8: 7 | O8: 3 | P8: 3 | R8: 3 | S8: =IF(SUM(Rankings!$K8:$R8)>0, COUNTIFS(Rankings!$D$2:$D$987, Rankings!$D8, Rankings!$F$2:$F$987, "<"&Rankings!$F8) + COUNTIFS(Rankings!$D$2:$D$987, Rankings!$D8, Rankings!$F$2:$F$987, Rankings!$F8, Rankings!$G$2:$G$987, "<"&Rankings!$G8)+1, "TBD") -> 4 | T8: 1 | U8: =Rankings!$S8=Rankings!$T8 -> FALSE
A9: 45910 | C9: {=INDEX(Rankings!$E$9:$E$15, MATCH(1, (Rankings!$D$9:$D$15=A9)*(Rankings!$U$9:$U$15=TRUE()), 0))} -> Giacomo | D9: =A9 -> 45910 | E9: =$K$1 -> Logan | F9: =IFERROR(AVERAGE(Rankings!$K9:$R9), "TBD") -> 4 | G9: =IFERROR(_xlfn.STDEV.P(Rankings!$K9:$R9), "TBD") -> 2.2038927 | H9: =IFERROR(AVERAGE(Rankings!$L9:$R9), "TBD") -> 4.3333333 | I9: Top 10 staTues tHat CriEd bloOd | J9: Bring Me The Horizon | K9: 2 | L9: 2 | M9: 7 | N9: 1 | O9: 6 | P9: 4 | R9: 6 | S9: =IF(SUM(Rankings!$K9:$R9)>0, COUNTIFS(Rankings!$D$2:$D$987, Rankings!$D9, Rankings!$F$2:$F$987, "<"&Rankings!$F9) + COUNTIFS(Rankings!$D$2:$D$987, Rankings!$D9, Rankings!$F$2:$F$987, Rankings!$F9, Rankings!$G$2:$G$987, "<"&Rankings!$G9)+1, "TBD") -> 4 | T9: 1 | U9: =Rankings!$S9=Rankings!$T9 -> FALSE
D10: =D9 -> 45910 | E10: =$L$1 -> Parker | F10: =IFERROR(AVERAGE(Rankings!$K10:$R10), "TBD") -> 2.7142857 | G10: =IFERROR(_xlfn.STDEV.P(Rankings!$K10:$R10), "TBD") -> 1.2777531 | H10: =IFERROR(AVERAGE(Rankings!$K10, Rankings!$M10:$R10), "TBD") -> 3 | I10: AURORA | J10: Mora, De La Rose | K10: 4 | L10: 1 | M10: 2 | N10: 4 | O10: 4 | P10: 3 | R10: 1 | S10: =IF(SUM(Rankings!$K10:$R10)>0, COUNTIFS(Rankings!$D$2:$D$987, Rankings!$D10, Rankings!$F$2:$F$987, "<"&Rankings!$F10) + COUNTIFS(Rankings!$D$2:$D$987, Rankings!$D10, Rankings!$F$2:$F$987, Rankings!$F10, Rankings!$G$2:$G$987, "<"&Rankings!$G10)+1, "TBD") -> 2 | T10: 1 | U10: =Rankings!$S10=Rankings!$T10 -> FALSE
D11: =D9 -> 45910 | E11: =$M$1 -> Giacomo | F11: =IFERROR(AVERAGE(Rankings!$K11:$R11), "TBD") -> 1.8571429 | G11: =IFERROR(_xlfn.STDEV.P(Rankings!$K11:$R11), "TBD") -> 0.83299313 | H11: =IFERROR(AVERAGE(Rankings!$K11:$L11, Rankings!$N11:$R11), "TBD") -> 2 | I11: SEE U DANCE | J11: Joey Valence & Brae, Rebecca Black | K11: 1 | L11: 3 | M11: 1 | N11: 3 | O11: 1 | P11: 2 | R11: 2 | S11: =IF(SUM(Rankings!$K11:$R11)>0, COUNTIFS(Rankings!$D$2:$D$987, Rankings!$D11, Rankings!$F$2:$F$987, "<"&Rankings!$F11) + COUNTIFS(Rankings!$D$2:$D$987, Rankings!$D11, Rankings!$F$2:$F$987, Rankings!$F11, Rankings!$G$2:$G$987, "<"&Rankings!$G11)+1, "TBD") -> 1 | T11: 1 | U11: =Rankings!$S11=Rankings!$T11 -> TRUE
D12: =D9 -> 45910 | E12: =$N$1 -> Rosey | F12: =IFERROR(AVERAGE(Rankings!$K12:$R12), "TBD") -> 5.1428571 | G12: =IFERROR(_xlfn.STDEV.P(Rankings!$K12:$R12), "TBD") -> 1.8070158 | H12: =IFERROR(AVERAGE(Rankings!$K12:$M12, Rankings!$O12:$R12), "TBD") -> 5.6666667 | I12: Tree | J12: Chance the Rapper, Smino, Lil Wayne | K12: 3 | L12: 6 | M12: 6 | N12: 2 | O12: 7 | P12: 7 | R12: 5 | S12: =IF(SUM(Rankings!$K12:$R12)>0, COUNTIFS(Rankings!$D$2:$D$987, Rankings!$D12, Rankings!$F$2:$F$987, "<"&Rankings!$F12) + COUNTIFS(Rankings!$D$2:$D$987, Rankings!$D12, Rankings!$F$2:$F$987, Rankings!$F12, Rankings!$G$2:$G$987, "<"&Rankings!$G12)+1, "TBD") -> 6 | T12: 1 | U12: =Rankings!$S12=Rankings!$T12 -> FALSE
D13: =D9 -> 45910 | E13: =$O$1 -> TTAC | F13: =IFERROR(AVERAGE(Rankings!$K13:$R13), "TBD") -> 6.2857143 | G13: =IFERROR(_xlfn.STDEV.P(Rankings!$K13:$R13), "TBD") -> 0.88063057 | H13: =IFERROR(AVERAGE(Rankings!$K13:$N13, Rankings!$P13:$R13), "TBD") -> 6.5 | I13: La Mamá de la Mamá | J13: El Alfa, Chael Produciendo, CJ | K13: 7 | L13: 7 | M13: 5 | N13: 7 | O13: 5 | P13: 6 | R13: 7 | S13: =IF(SUM(Rankings!$K13:$R13)>0, COUNTIFS(Rankings!$D$2:$D$987, Rankings!$D13, Rankings!$F$2:$F$987, "<"&Rankings!$F13) + COUNTIFS(Rankings!$D$2:$D$987, Rankings!$D13, Rankings!$F$2:$F$987, Rankings!$F13, Rankings!$G$2:$G$987, "<"&Rankings!$G13)+1, "TBD") -> 7 | T13: 1 | U13: =Rankings!$S13=Rankings!$T13 -> FALSE
D14: =D10 -> 45910 | E14: =$P$1 -> Weston | F14: =IFERROR(AVERAGE(Rankings!$K14:$R14), "TBD") -> 3.8571429 | G14: =IFERROR(_xlfn.STDEV.P(Rankings!$K14:$R14), "TBD") -> 1.7261494 | H14: =IFERROR(AVERAGE(Rankings!$K14:$O14, Rankings!$R14), "TBD") -> 4.3333333 | I14: The Artist in the Ambulance | J14: Thrice | K14: 6 | L14: 4 | M14: 4 | N14: 6 | O14: 2 | P14: 1 | R14: 4 | S14: =IF(SUM(Rankings!$K14:$R14)>0, COUNTIFS(Rankings!$D$2:$D$987, Rankings!$D14, Rankings!$F$2:$F$987, "<"&Rankings!$F14) + COUNTIFS(Rankings!$D$2:$D$987, Rankings!$D14, Rankings!$F$2:$F$987, Rankings!$F14, Rankings!$G$2:$G$987, "<"&Rankings!$G14)+1, "TBD") -> 3 | T14: 1 | U14: =Rankings!$S14=Rankings!$T14 -> FALSE
D15: =D11 -> 45910 | E15: =$R$1 -> Jake | F15: =IFERROR(AVERAGE(Rankings!$K15:$R15), "TBD") -> 4.1428571 | G15: =IFERROR(_xlfn.STDEV.P(Rankings!$K15:$R15), "TBD") -> 0.98974332 | H15: =IFERROR(AVERAGE(Rankings!$K15:$P15), "TBD") -> 4.3333333 | I15: Indigo | J15: Magnolian | K15: 5 | L15: 5 | M15: 3 | N15: 5 | O15: 3 | P15: 5 | R15: 3 | S15: =IF(SUM(Rankings!$K15:$R15)>0, COUNTIFS(Rankings!$D$2:$D$987, Rankings!$D15, Rankings!$F$2:$F$987, "<"&Rankings!$F15) + COUNTIFS(Rankings!$D$2:$D$987, Rankings!$D15, Rankings!$F$2:$F$987, Rankings!$F15, Rankings!$G$2:$G$987, "<"&Rankings!$G15)+1, "TBD") -> 5 | T15: 1 | U15: =Rankings!$S15=Rankings!$T15 -> FALSE
A16: 45912 | C16: {=INDEX(Rankings!$E$16:$E$22, MATCH(1, (Rankings!$D$16:$D$22=A16)*(Rankings!$U$16:$U$22=TRUE()), 0))} -> Rosey | D16: =A16 -> 45912 | E16: =$K$1 -> Logan | F16: =IFERROR(AVERAGE(Rankings!$K16:$R16), "TBD") -> 3.2857143 | G16: =IFERROR(_xlfn.STDEV.P(Rankings!$K16:$R16), "TBD") -> 1.905952 | H16: =IFERROR(AVERAGE(Rankings!$L16:$R16), "TBD") -> 3.6666667 | I16: Candle Flame | J16: Jungle, Erick the Architect | K16: 1 | L16: 4 | M16: 3 | N16: 3 | O16: 7 | P16: 4 | R16: 1 | S16: =IF(SUM(Rankings!$K16:$R16)>0, COUNTIFS(Rankings!$D$2:$D$987, Rankings!$D16, Rankings!$F$2:$F$987, "<"&Rankings!$F16) + COUNTIFS(Rankings!$D$2:$D$987, Rankings!$D16, Rankings!$F$2:$F$987, Rankings!$F16, Rankings!$G$2:$G$987, "<"&Rankings!$G16)+1, "TBD") -> 2 | T16: 1 | U16: =Rankings!$S16=Rankings!$T16 -> FALSE
D17: =D16 -> 45912 | E17: =$L$1 -> Parker | F17: =IFERROR(AVERAGE(Rankings!$K17:$R17), "TBD") -> 4 | G17: =IFERROR(_xlfn.STDEV.P(Rankings!$K17:$R17), "TBD") -> 1.9272482 | H17: =IFERROR(AVERAGE(Rankings!$K17, Rankings!$M17:$R17), "TBD") -> 4.5 | I17: Bros | J17: Wolf Alice | K17: 6 | L17: 1 | M17: 4 | N17: 6 | O17: 2 | P17: 3 | R17: 6 | S17: =IF(SUM(Rankings!$K17:$R17)>0, COUNTIFS(Rankings!$D$2:$D$987, Rankings!$D17, Rankings!$F$2:$F$987, "<"&Rankings!$F17) + COUNTIFS(Rankings!$D$2:$D$987, Rankings!$D17, Rankings!$F$2:$F$987, Rankings!$F17, Rankings!$G$2:$G$987, "<"&Rankings!$G17)+1, "TBD") -> 3 | T17: 1 | U17: =Rankings!$S17=Rankings!$T17 -> FALSE
D18: =D16 -> 45912 | E18: =$M$1 -> Giacomo | F18: =IFERROR(AVERAGE(Rankings!$K18:$R18), "TBD") -> 4.2857143 | G18: =IFERROR(_xlfn.STDEV.P(Rankings!$K18:$R18), "TBD") -> 1.484615 | H18: =IFERROR(AVERAGE(Rankings!$K18:$L18, Rankings!$N18:$R18), "TBD") -> 4.6666667 | I18: move it along | J18: Sasha Keable, Leon Thomas | K18: 5 | L18: 2 | M18: 2 | N18: 5 | O18: 6 | P18: 5 | R18: 5 | S18: =IF(SUM(Rankings!$K18:$R18)>0, COUNTIFS(Rankings!$D$2:$D$987, Rankings!$D18, Rankings!$F$2:$F$987, "<"&Rankings!$F18) + COUNTIFS(Rankings!$D$2:$D$987, Rankings!$D18, Rankings!$F$2:$F$987, Rankings!$F18, Rankings!$G$2:$G$987, "<"&Rankings!$G18)+1, "TBD") -> 4 | T18: 1 | U18: =Rankings!$S18=Rankings!$T18 -> FALSE
D19: =D16 -> 45912 | E19: =$N$1 -> Rosey | F19: =IFERROR(AVERAGE(Rankings!$K19:$R19), "TBD") -> 2.8571429 | G19: =IFERROR(_xlfn.STDEV.P(Rankings!$K19:$R19), "TBD") -> 1.8070158 | H19: =IFERROR(AVERAGE(Rankings!$K19:$M19, Rankings!$O19:$R19), "TBD") -> 3.1666667 | I19: Helena Beat | J19: Foster the People | K19: 2 | L19: 6 | M19: 5 | N19: 1 | O19: 3 | P19: 1 | R19: 2 | S19: =IF(SUM(Rankings!$K19:$R19)>0, COUNTIFS(Rankings!$D$2:$D$987, Rankings!$D19, Rankings!$F$2:$F$987, "<"&Rankings!$F19) + COUNTIFS(Rankings!$D$2:$D$987, Rankings!$D19, Rankings!$F$2:$F$987, Rankings!$F19, Rankings!$G$2:$G$987, "<"&Rankings!$G19)+1, "TBD") -> 1 | T19: 1 | U19: =Rankings!$S19=Rankings!$T19 -> TRUE
D20: =D16 -> 45912 | E20: =$O$1 -> TTAC | F20: =IFERROR(AVERAGE(Rankings!$K20:$R20), "TBD") -> 4.2857143 | G20: =IFERROR(_xlfn.STDEV.P(Rankings!$K20:$R20), "TBD") -> 2.5475078 | H20: =IFERROR(AVERAGE(Rankings!$K20:$N20, Rankings!$P20:$R20), "TBD") -> 4.8333333 | I20: PROM/KING | J20: Saba | K20: 4 | L20: 3 | M20: 1 | N20: 7 | O20: 1 | P20: 7 | R20: 7 | S20: =IF(SUM(Rankings!$K20:$R20)>0, COUNTIFS(Rankings!$D$2:$D$987, Rankings!$D20, Rankings!$F$2:$F$987, "<"&Rankings!$F20) + COUNTIFS(Rankings!$D$2:$D$987, Rankings!$D20, Rankings!$F$2:$F$987, Rankings!$F20, Rankings!$G$2:$G$987, "<"&Rankings!$G20)+1, "TBD") -> 5 | T20: 1 | U20: =Rankings!$S20=Rankings!$T20 -> FALSE
D21: =D17 -> 45912 | E21: =$P$1 -> Weston | F21: =IFERROR(AVERAGE(Rankings!$K21:$R21), "TBD") -> 4.7142857 | G21: =IFERROR(_xlfn.STDEV.P(Rankings!$K21:$R21), "TBD") -> 2.1189139 | H21: =IFERROR(AVERAGE(Rankings!$K21:$O21, Rankings!$R21), "TBD") -> 5.1666667 | I21: The Kiss of Venus (Dominic Fike) | J21: Paul McCartney, Dominic Fike | K21: 7 | L21: 7 | M21: 7 | N21: 2 | O21: 4 | P21: 2 | R21: 4 | S21: =IF(SUM(Rankings!$K21:$R21)>0, COUNTIFS(Rankings!$D$2:$D$987, Rankings!$D21, Rankings!$F$2:$F$987, "<"&Rankings!$F21) + COUNTIFS(Rankings!$D$2:$D$987, Rankings!$D21, Rankings!$F$2:$F$987, Rankings!$F21, Rankings!$G$2:$G$987, "<"&Rankings!$G21)+1, "TBD") -> 7 | T21: 1 | U21: =Rankings!$S21=Rankings!$T21 -> FALSE
D22: =D18 -> 45912 | E22: =$R$1 -> Jake | F22: =IFERROR(AVERAGE(Rankings!$K22:$R22), "TBD") -> 4.5714286 | G22: =IFERROR(_xlfn.STDEV.P(Rankings!$K22:$R22), "TBD") -> 1.1780302 | H22: =IFERROR(AVERAGE(Rankings!$K22:$P22), "TBD") -> 4.8333333 | I22: Pressure | J22: Billy Joel | K22: 3 | L22: 5 | M22: 6 | N22: 4 | O22: 5 | P22: 6 | R22: 3 | S22: =IF(SUM(Rankings!$K22:$R22)>0, COUNTIFS(Rankings!$D$2:$D$987, Rankings!$D22, Rankings!$F$2:$F$987, "<"&Rankings!$F22) + COUNTIFS(Rankings!$D$2:$D$987, Rankings!$D22, Rankings!$F$2:$F$987, Rankings!$F22, Rankings!$G$2:$G$987, "<"&Rankings!$G22)+1, "TBD") -> 6 | T22: 1 | U22: =Rankings!$S22=Rankings!$T22 -> FALSE
A23: 45915 | C23: {=INDEX(Rankings!$E23:$E29, MATCH(1, (Rankings!$D23:$D29=$A23)*(Rankings!$U23:$U29=TRUE()), 0))} -> Rosey | D23: =A23 -> 45915 | E23: =$K$1 -> Logan | F23: =IFERROR(AVERAGE(Rankings!$K23:$R23), "TBD") -> 3.5714286 | G23: =IFERROR(_xlfn.STDEV.P(Rankings!$K23:$R23), "TBD") -> 1.4982984 | H23: =IFERROR(AVERAGE(Rankings!$L23:$R23), "TBD") -> 4 | I23: Politix | J23: Balu Brigada | K23: 1 | L23: 3 | M23: 5 | N23: 6 | O23: 3 | P23: 3 | R23: 4 | S23: =IF(SUM(Rankings!$K23:$R23)>0, COUNTIFS(Rankings!$D$2:$D$987, Rankings!$D23, Rankings!$F$2:$F$987, "<"&Rankings!$F23) + COUNTIFS(Rankings!$D$2:$D$987, Rankings!$D23, Rankings!$F$2:$F$987, Rankings!$F23, Rankings!$G$2:$G$987, "<"&Rankings!$G23)+1, "TBD") -> 2 | T23: 1 | U23: =Rankings!$S23=Rankings!$T23 -> FALSE
D24: =D23 -> 45915 | E24: =$L$1 -> Parker | F24: =IFERROR(AVERAGE(Rankings!$K24:$R24), "TBD") -> 3.7142857 | G24: =IFERROR(_xlfn.STDEV.P(Rankings!$K24:$R24), "TBD") -> 1.7496355 | H24: =IFERROR(AVERAGE(Rankings!$K24, Rankings!$M24:$R24), "TBD") -> 4 | I24: BUBALU | J24: Feid,Rema | K24: 2 | L24: 2 | M24: 3 | N24: 2 | O24: 6 | P24: 6 | R24: 5 | S24: =IF(SUM(Rankings!$K24:$R24)>0, COUNTIFS(Rankings!$D$2:$D$987, Rankings!$D24, Rankings!$F$2:$F$987, "<"&Rankings!$F24) + COUNTIFS(Rankings!$D$2:$D$987, Rankings!$D24, Rankings!$F$2:$F$987, Rankings!$F24, Rankings!$G$2:$G$987, "<"&Rankings!$G24)+1, "TBD") -> 3 | T24: 1 | U24: =Rankings!$S24=Rankings!$T24 -> FALSE
D25: =D23 -> 45915 | E25: =$M$1 -> Giacomo | F25: =IFERROR(AVERAGE(Rankings!$K25:$R25), "TBD") -> 3.8571429 | G25: =IFERROR(_xlfn.STDEV.P(Rankings!$K25:$R25), "TBD") -> 1.5518258 | H25: =IFERROR(AVERAGE(Rankings!$K25:$L25, Rankings!$N25:$R25), "TBD") -> 4.1666667 | I25: mudbone | J25: Paris Texas | K25: 3 | L25: 4 | M25: 2 | N25: 3 | O25: 7 | P25: 5 | R25: 3 | S25: =IF(SUM(Rankings!$K25:$R25)>0, COUNTIFS(Rankings!$D$2:$D$987, Rankings!$D25, Rankings!$F$2:$F$987, "<"&Rankings!$F25) + COUNTIFS(Rankings!$D$2:$D$987, Rankings!$D25, Rankings!$F$2:$F$987, Rankings!$F25, Rankings!$G$2:$G$987, "<"&Rankings!$G25)+1, "TBD") -> 4 | T25: 1 | U25: =Rankings!$S25=Rankings!$T25 -> FALSE
D26: =D23 -> 45915 | E26: =$N$1 -> Rosey | F26: =IFERROR(AVERAGE(Rankings!$K26:$R26), "TBD") -> 2.4285714 | G26: =IFERROR(_xlfn.STDEV.P(Rankings!$K26:$R26), "TBD") -> 2.1285235 | H26: =IFERROR(AVERAGE(Rankings!$K26:$M26, Rankings!$O26:$R26), "TBD") -> 2.6666667 | I26: On My Own | J26: Jaden, Kid Cudi | K26: 4 | L26: 1 | M26: 7 | N26: 1 | O26: 2 | P26: 1 | R26: 1 | S26: =IF(SUM(Rankings!$K26:$R26)>0, COUNTIFS(Rankings!$D$2:$D$987, Rankings!$D26, Rankings!$F$2:$F$987, "<"&Rankings!$F26) + COUNTIFS(Rankings!$D$2:$D$987, Rankings!$D26, Rankings!$F$2:$F$987, Rankings!$F26, Rankings!$G$2:$G$987, "<"&Rankings!$G26)+1, "TBD") -> 1 | T26: 1 | U26: =Rankings!$S26=Rankings!$T26 -> TRUE
D27: =D23 -> 45915 | E27: =$O$1 -> TTAC | F27: =IFERROR(AVERAGE(Rankings!$K27:$R27), "TBD") -> 5.4285714 | G27: =IFERROR(_xlfn.STDEV.P(Rankings!$K27:$R27), "TBD") -> 2.060315 | H27: =IFERROR(AVERAGE(Rankings!$K27:$N27, Rankings!$P27:$R27), "TBD") -> 6.1666667 | I27: Brunette | J27: Tucker Wetmore | K27: 6 | L27: 7 | M27: 6 | N27: 4 | O27: 1 | P27: 7 | R27: 7 | S27: =IF(SUM(Rankings!$K27:$R27)>0, COUNTIFS(Rankings!$D$2:$D$987, Rankings!$D27, Rankings!$F$2:$F$987, "<"&Rankings!$F27) + COUNTIFS(Rankings!$D$2:$D$987, Rankings!$D27, Rankings!$F$2:$F$987, Rankings!$F27, Rankings!$G$2:$G$987, "<"&Rankings!$G27)+1, "TBD") -> 7 | T27: 1 | U27: =Rankings!$S27=Rankings!$T27 -> FALSE
D28: =D24 -> 45915 | E28: =$P$1 -> Weston | F28: =IFERROR(AVERAGE(Rankings!$K28:$R28), "TBD") -> 4.7142857 | G28: =IFERROR(_xlfn.STDEV.P(Rankings!$K28:$R28), "TBD") -> 2.2497165 | H28: =IFERROR(AVERAGE(Rankings!$K28:$O28, Rankings!$R28), "TBD") -> 5.1666667 | I28: Sedona | J28: Houndmouth | K28: 7 | L28: 6 | M28: 1 | N28: 7 | O28: 4 | P28: 2 | R28: 6 | S28: =IF(SUM(Rankings!$K28:$R28)>0, COUNTIFS(Rankings!$D$2:$D$987, Rankings!$D28, Rankings!$F$2:$F$987, "<"&Rankings!$F28) + COUNTIFS(Rankings!$D$2:$D$987, Rankings!$D28, Rankings!$F$2:$F$987, Rankings!$F28, Rankings!$G$2:$G$987, "<"&Rankings!$G28)+1, "TBD") -> 6 | T28: 1 | U28: =Rankings!$S28=Rankings!$T28 -> FALSE
D29: =D25 -> 45915 | E29: =$R$1 -> Jake | F29: =IFERROR(AVERAGE(Rankings!$K29:$R29), "TBD") -> 4.2857143 | G29: =IFERROR(_xlfn.STDEV.P(Rankings!$K29:$R29), "TBD") -> 1.0301575 | H29: =IFERROR(AVERAGE(Rankings!$K29:$P29), "TBD") -> 4.6666667 | I29: Heavy | J29: The Marias | K29: 5 | L29: 5 | M29: 4 | N29: 5 | O29: 5 | P29: 4 | R29: 2 | S29: =IF(SUM(Rankings!$K29:$R29)>0, COUNTIFS(Rankings!$D$2:$D$987, Rankings!$D29, Rankings!$F$2:$F$987, "<"&Rankings!$F29) + COUNTIFS(Rankings!$D$2:$D$987, Rankings!$D29, Rankings!$F$2:$F$987, Rankings!$F29, Rankings!$G$2:$G$987, "<"&Rankings!$G29)+1, "TBD") -> 5 | T29: 1 | U29: =Rankings!$S29=Rankings!$T29 -> FALSE
A30: 45917 | C30: {=INDEX(Rankings!$E30:$E36, MATCH(1, (Rankings!$D30:$D36=$A30)*(Rankings!$U30:$U36=TRUE()), 0))} -> Parker | D30: =A30 -> 45917 | E30: =$K$1 -> Logan | F30: =IFERROR(AVERAGE(Rankings!$K30:$R30), "TBD") -> 3.7142857 | G30: =IFERROR(_xlfn.STDEV.P(Rankings!$K30:$R30), "TBD") -> 1.905952 | H30: =IFERROR(AVERAGE(Rankings!$L30:$R30), "TBD") -> 4 | I30: FAMJAM4000 | J30: Jordan Ward | K30: 2 | L30: 5 | M30: 4 | N30: 6 | O30: 6 | P30: 1 | R30: 2 | S30: =IF(SUM(Rankings!$K30:$R30)>0, COUNTIFS(Rankings!$D$2:$D$987, Rankings!$D30, Rankings!$F$2:$F$987, "<"&Rankings!$F30) + COUNTIFS(Rankings!$D$2:$D$987, Rankings!$D30, Rankings!$F$2:$F$987, Rankings!$F30, Rankings!$G$2:$G$987, "<"&Rankings!$G30)+1, "TBD") -> 4 | T30: 1 | U30: =Rankings!$S30=Rankings!$T30 -> FALSE
D31: =D30 -> 45917 | E31: =$L$1 -> Parker | F31: =IFERROR(AVERAGE(Rankings!$K31:$R31), "TBD") -> 2.8571429 | G31: =IFERROR(_xlfn.STDEV.P(Rankings!$K31:$R31), "TBD") -> 1.6413036 | H31: =IFERROR(AVERAGE(Rankings!$K31, Rankings!$M31:$R31), "TBD") -> 3 | I31: Étouffée | J31: Vince Staples | K31: 4 | L31: 2 | M31: 1 | N31: 1 | O31: 3 | P31: 3 | R31: 6 | S31: =IF(SUM(Rankings!$K31:$R31)>0, COUNTIFS(Rankings!$D$2:$D$987, Rankings!$D31, Rankings!$F$2:$F$987, "<"&Rankings!$F31) + COUNTIFS(Rankings!$D$2:$D$987, Rankings!$D31, Rankings!$F$2:$F$987, Rankings!$F31, Rankings!$G$2:$G$987, "<"&Rankings!$G31)+1, "TBD") -> 1 | T31: 1 | U31: =Rankings!$S31=Rankings!$T31 -> TRUE
D32: =D30 -> 45917 | E32: =$M$1 -> Giacomo | F32: =IFERROR(AVERAGE(Rankings!$K32:$R32), "TBD") -> 4 | G32: =IFERROR(_xlfn.STDEV.P(Rankings!$K32:$R32), "TBD") -> 1.7728105 | H32: =IFERROR(AVERAGE(Rankings!$K32:$L32, Rankings!$N32:$R32), "TBD") -> 4.1666667 | I32: How Can I Love Her More? | J32: The Lemon Twigs | K32: 6 | L32: 4 | M32: 3 | N32: 2 | O32: 2 | P32: 7 | R32: 4 | S32: =IF(SUM(Rankings!$K32:$R32)>0, COUNTIFS(Rankings!$D$2:$D$987, Rankings!$D32, Rankings!$F$2:$F$987, "<"&Rankings!$F32) + COUNTIFS(Rankings!$D$2:$D$987, Rankings!$D32, Rankings!$F$2:$F$987, Rankings!$F32, Rankings!$G$2:$G$987, "<"&Rankings!$G32)+1, "TBD") -> 5 | T32: 1 | U32: =Rankings!$S32=Rankings!$T32 -> FALSE
D33: =D30 -> 45917 | E33: =$N$1 -> Rosey | F33: =IFERROR(AVERAGE(Rankings!$K33:$R33), "TBD") -> 5 | G33: =IFERROR(_xlfn.STDEV.P(Rankings!$K33:$R33), "TBD") -> 2.1380899 | H33: =IFERROR(AVERAGE(Rankings!$K33:$M33, Rankings!$O33:$R33), "TBD") -> 5.3333333 | I33: Paradox | J33: Survive Said the Prophet | K33: 1 | L33: 7 | M33: 7 | N33: 3 | O33: 5 | P33: 5 | R33: 7 | S33: =IF(SUM(Rankings!$K33:$R33)>0, COUNTIFS(Rankings!$D$2:$D$987, Rankings!$D33, Rankings!$F$2:$F$987, "<"&Rankings!$F33) + COUNTIFS(Rankings!$D$2:$D$987, Rankings!$D33, Rankings!$F$2:$F$987, Rankings!$F33, Rankings!$G$2:$G$987, "<"&Rankings!$G33)+1, "TBD") -> 6 | T33: 1 | U33: =Rankings!$S33=Rankings!$T33 -> FALSE
D34: =D30 -> 45917 | E34: =$O$1 -> TTAC | F34: =IFERROR(AVERAGE(Rankings!$K34:$R34), "TBD") -> 3.2857143 | G34: =IFERROR(_xlfn.STDEV.P(Rankings!$K34:$R34), "TBD") -> 1.5779087 | H34: =IFERROR(AVERAGE(Rankings!$K34:$N34, Rankings!$P34:$R34), "TBD") -> 3.6666667 | I34: Solsbury Hill | J34: Peter Gabriel | K34: 5 | L34: 3 | M34: 5 | N34: 4 | O34: 1 | P34: 4 | R34: 1 | S34: =IF(SUM(Rankings!$K34:$R34)>0, COUNTIFS(Rankings!$D$2:$D$987, Rankings!$D34, Rankings!$F$2:$F$987, "<"&Rankings!$F34) + COUNTIFS(Rankings!$D$2:$D$987, Rankings!$D34, Rankings!$F$2:$F$987, Rankings!$F34, Rankings!$G$2:$G$987, "<"&Rankings!$G34)+1, "TBD") -> 2 | T34: 1 | U34: =Rankings!$S34=Rankings!$T34 -> FALSE
D35: =D31 -> 45917 | E35: =$P$1 -> Weston | F35: =IFERROR(AVERAGE(Rankings!$K35:$R35), "TBD") -> 3.2857143 | G35: =IFERROR(_xlfn.STDEV.P(Rankings!$K35:$R35), "TBD") -> 1.905952 | H35: =IFERROR(AVERAGE(Rankings!$K35:$O35, Rankings!$R35), "TBD") -> 3.5 | I35: Drugs you should try it | J35: Travis Scott | K35: 3 | L35: 1 | M35: 2 | N35: 5 | O35: 7 | P35: 2 | R35: 3 | S35: =IF(SUM(Rankings!$K35:$R35)>0, COUNTIFS(Rankings!$D$2:$D$987, Rankings!$D35, Rankings!$F$2:$F$987, "<"&Rankings!$F35) + COUNTIFS(Rankings!$D$2:$D$987, Rankings!$D35, Rankings!$F$2:$F$987, Rankings!$F35, Rankings!$G$2:$G$987, "<"&Rankings!$G35)+1, "TBD") -> 3 | T35: 1 | U35: =Rankings!$S35=Rankings!$T35 -> FALSE
D36: =D32 -> 45917 | E36: =$R$1 -> Jake | F36: =IFERROR(AVERAGE(Rankings!$K36:$R36), "TBD") -> 5.8571429 | G36: =IFERROR(_xlfn.STDEV.P(Rankings!$K36:$R36), "TBD") -> 0.98974332 | H36: =IFERROR(AVERAGE(Rankings!$K36:$P36), "TBD") -> 6 | I36: Save Your Soul | J36: Kathleen Edwards | K36: 7 | L36: 6 | M36: 6 | N36: 7 | O36: 4 | P36: 6 | R36: 5 | S36: =IF(SUM(Rankings!$K36:$R36)>0, COUNTIFS(Rankings!$D$2:$D$987, Rankings!$D36, Rankings!$F$2:$F$987, "<"&Rankings!$F36) + COUNTIFS(Rankings!$D$2:$D$987, Rankings!$D36, Rankings!$F$2:$F$987, Rankings!$F36, Rankings!$G$2:$G$987, "<"&Rankings!$G36)+1, "TBD") -> 7 | T36: 1 | U36: =Rankings!$S36=Rankings!$T36 -> FALSE
A37: 45919 | C37: {=INDEX(Rankings!$E37:$E43, MATCH(1, (Rankings!$D37:$D43=$A37)*(Rankings!$U37:$U43=TRUE()), 0))} -> Rosey | D37: =A37 -> 45919 | E37: =$K$1 -> Logan | F37: =IFERROR(AVERAGE(Rankings!$K37:$R37), "TBD") -> 5.1428571 | G37: =IFERROR(_xlfn.STDEV.P(Rankings!$K37:$R37), "TBD") -> 1.8070158 | H37: =IFERROR(AVERAGE(Rankings!$L37:$R37), "TBD") -> 5.6666667 | I37: ROLLER COASTER | J37: legallyrxx | K37: 2 | L37: 4 | M37: 4 | N37: 5 | O37: 7 | P37: 7 | R37: 7 | S37: =IF(SUM(Rankings!$K37:$R37)>0, COUNTIFS(Rankings!$D$2:$D$987, Rankings!$D37, Rankings!$F$2:$F$987, "<"&Rankings!$F37) + COUNTIFS(Rankings!$D$2:$D$987, Rankings!$D37, Rankings!$F$2:$F$987, Rankings!$F37, Rankings!$G$2:$G$987, "<"&Rankings!$G37)+1, "TBD") -> 7 | T37: 1 | U37: =Rankings!$S37=Rankings!$T37 -> FALSE | W37: First sweep, racism test passed :)
D38: =D37 -> 45919 | E38: =$L$1 -> Parker | F38: =IFERROR(AVERAGE(Rankings!$K38:$R38), "TBD") -> 3.5714286 | G38: =IFERROR(_xlfn.STDEV.P(Rankings!$K38:$R38), "TBD") -> 1.2936264 | H38: =IFERROR(AVERAGE(Rankings!$K38, Rankings!$M38:$R38), "TBD") -> 3.8333333 | I38: Kitchen | J38: Kid Cudi | K38: 5 | L38: 2 | M38: 3 | N38: 2 | O38: 5 | P38: 5 | R38: 3 | S38: =IF(SUM(Rankings!$K38:$R38)>0, COUNTIFS(Rankings!$D$2:$D$987, Rankings!$D38, Rankings!$F$2:$F$987, "<"&Rankings!$F38) + COUNTIFS(Rankings!$D$2:$D$987, Rankings!$D38, Rankings!$F$2:$F$987, Rankings!$F38, Rankings!$G$2:$G$987, "<"&Rankings!$G38)+1, "TBD") -> 2 | T38: 1 | U38: =Rankings!$S38=Rankings!$T38 -> FALSE
D39: =D37 -> 45919 | E39: =$M$1 -> Giacomo | F39: =IFERROR(AVERAGE(Rankings!$K39:$R39), "TBD") -> 3.8571429 | G39: =IFERROR(_xlfn.STDEV.P(Rankings!$K39:$R39), "TBD") -> 1.3552619 | H39: =IFERROR(AVERAGE(Rankings!$K39:$L39, Rankings!$N39:$R39), "TBD") -> 4.1666667 | I39: Buenos tiempos | J39: Dillom | K39: 6 | L39: 5 | M39: 2 | N39: 4 | O39: 4 | P39: 4 | R39: 2 | S39: =IF(SUM(Rankings!$K39:$R39)>0, COUNTIFS(Rankings!$D$2:$D$987, Rankings!$D39, Rankings!$F$2:$F$987, "<"&Rankings!$F39) + COUNTIFS(Rankings!$D$2:$D$987, Rankings!$D39, Rankings!$F$2:$F$987, Rankings!$F39, Rankings!$G$2:$G$987, "<"&Rankings!$G39)+1, "TBD") -> 3 | T39: 1 | U39: =Rankings!$S39=Rankings!$T39 -> FALSE
D40: =D37 -> 45919 | E40: =$N$1 -> Rosey | F40: =IFERROR(AVERAGE(Rankings!$K40:$R40), "TBD") -> 1 | G40: =IFERROR(_xlfn.STDEV.P(Rankings!$K40:$R40), "TBD") -> 0 | H40: =IFERROR(AVERAGE(Rankings!$K40:$M40, Rankings!$O40:$R40), "TBD") -> 1 | I40: TEMPTATION | J40: Joey Bada$$ | K40: 1 | L40: 1 | M40: 1 | N40: 1 | O40: 1 | P40: 1 | R40: 1 | S40: =IF(SUM(Rankings!$K40:$R40)>0, COUNTIFS(Rankings!$D$2:$D$987, Rankings!$D40, Rankings!$F$2:$F$987, "<"&Rankings!$F40) + COUNTIFS(Rankings!$D$2:$D$987, Rankings!$D40, Rankings!$F$2:$F$987, Rankings!$F40, Rankings!$G$2:$G$987, "<"&Rankings!$G40)+1, "TBD") -> 1 | T40: 1 | U40: =Rankings!$S40=Rankings!$T40 -> TRUE
...

Sheet Leaderboard
B2: =CONCAT("Day ",COUNTIF(Rankings!A:A,"<="&TODAY())) -> Day 165 | C2: Number of Wins | D2: Sum of Average | E2: Overall Average | F2: Place | G2: Constructors
B3: =Rankings!$K$1 -> Logan | C3: =COUNTIFS(Rankings!$E$2:$E$987,$B3, Rankings!$U$2:$U$987,TRUE()) -> 15 | D3: {=SUM(IF(Rankings!$E$2:$E$987=$B3, Rankings!$F$2:$F$987))} -> 557.73333 | E3: {=AVERAGE(IF(Rankings!$E$2:$E$987=$B3, Rankings!$F$2:$F$987))} -> 3.9002331 | F3: =_xlfn.RANK.EQ(C3,$C$3:$C$10,0) -> 5 | G3: =_xlfn.RANK.EQ(E3,$E$3:$E$10,1) -> 6
B4: =Rankings!$L$1 -> Parker | C4: =COUNTIFS(Rankings!$E$2:$E$987,$B4, Rankings!$U$2:$U$987,TRUE()) -> 22 | D4: {=SUM(IF(Rankings!$E$2:$E$987=$B4, Rankings!$F$2:$F$987))} -> 517.86667 | E4: {=AVERAGE(IF(Rankings!$E$2:$E$987=$B4, Rankings!$F$2:$F$987))} -> 3.6214452 | F4: =_xlfn.RANK.EQ(C4,$C$3:$C$10,0) -> 3 | G4: =_xlfn.RANK.EQ(E4,$E$3:$E$10,1) -> 2
B5: =Rankings!$M$1 -> Giacomo | C5: =COUNTIFS(Rankings!$E$2:$E$987,$B5, Rankings!$U$2:$U$987,TRUE()) -> 20 | D5: {=SUM(IF(Rankings!$E$2:$E$987=$B5, Rankings!$F$2:$F$987))} -> 518.9 | E5: {=AVERAGE(IF(Rankings!$E$2:$E$987=$B5, Rankings!$F$2:$F$987))} -> 3.6286713 | F5: =_xlfn.RANK.EQ(C5,$C$3:$C$10,0) -> 4 | G5: =_xlfn.RANK.EQ(E5,$E$3:$E$10,1) -> 3
B6: =Rankings!$N$1 -> Rosey | C6: =COUNTIFS(Rankings!$E$2:$E$987,$B6, Rankings!$U$2:$U$987,TRUE()) -> 26 | D6: {=SUM(IF(Rankings!$E$2:$E$987=$B6, Rankings!$F$2:$F$987))} -> 378.78571 | E6: {=AVERAGE(IF(Rankings!$E$2:$E$987=$B6, Rankings!$F$2:$F$987))} -> 3.6421703 | F6: =_xlfn.RANK.EQ(C6,$C$3:$C$10,0) -> 2 | G6: =_xlfn.RANK.EQ(E6,$E$3:$E$10,1) -> 5
B7: =Rankings!$O$1 -> TTAC | C7: =COUNTIFS(Rankings!$E$2:$E$987,$B7, Rankings!$U$2:$U$987,TRUE()) -> 12 | D7: {=SUM(IF(Rankings!$E$2:$E$987=$B7, Rankings!$F$2:$F$987))} -> 632.40476 | E7: {=AVERAGE(IF(Rankings!$E$2:$E$987=$B7, Rankings!$F$2:$F$987))} -> 4.4535547 | F7: =_xlfn.RANK.EQ(C7,$C$3:$C$10,0) -> 7 | G7: =_xlfn.RANK.EQ(E7,$E$3:$E$10,1) -> 8
B8: =Rankings!$P$1 -> Weston | C8: =COUNTIFS(Rankings!$E$2:$E$987,$B8, Rankings!$U$2:$U$987,TRUE()) -> 30 | D8: {=SUM(IF(Rankings!$E$2:$E$987=$B8, Rankings!$F$2:$F$987))} -> 512.04762 | E8: {=AVERAGE(IF(Rankings!$E$2:$E$987=$B8, Rankings!$F$2:$F$987))} -> 3.6059691 | F8: =_xlfn.RANK.EQ(C8,$C$3:$C$10,0) -> 1 | G8: =_xlfn.RANK.EQ(E8,$E$3:$E$10,1) -> 1
B9: =Rankings!$R$1 -> Jake | C9: =COUNTIFS(Rankings!$E$2:$E$987,$B9, Rankings!$U$2:$U$987,TRUE()) -> 2 | D9: {=SUM(IF(Rankings!$E$2:$E$987=$B9, Rankings!$F$2:$F$987))} -> 209.02381 | E9: {=AVERAGE(IF(Rankings!$E$2:$E$987=$B9, Rankings!$F$2:$F$987))} -> 4.265792 | F9: =_xlfn.RANK.EQ(C9,$C$3:$C$10,0) -> 8 | G9: =_xlfn.RANK.EQ(E9,$E$3:$E$10,1) -> 7
B10: =Rankings!$Q$1 -> Flocco | C10: =COUNTIFS(Rankings!$E$2:$E$987,$B10, Rankings!$U$2:$U$987,TRUE()) -> 15 | D10: {=SUM(IF(Rankings!$E$2:$E$987=$B10, Rankings!$F$2:$F$987))} -> 272.19048 | E10: {=AVERAGE(IF(Rankings!$E$2:$E$987=$B10, Rankings!$F$2:$F$987))} -> 3.6292063 | F10: =_xlfn.RANK.EQ(C10,$C$3:$C$10,0) -> 5 | G10: =_xlfn.RANK.EQ(E10,$E$3:$E$10,1) -> 4
B12: Average Rank
B13: Poster/Voter | C13: =Rankings!$K$1 -> Logan | D13: =Rankings!$L$1 -> Parker | E13: =Rankings!$M$1 -> Giacomo | F13: =Rankings!$N$1 -> Rosey | G13: =Rankings!$O$1 -> TTAC | H13: =Rankings!$P$1 -> Weston | I13: =Rankings!$R$1 -> Jake | J13: =Rankings!$Q$1 -> Flocco
B14: =Rankings!$K$1 -> Logan | C14: =AVERAGEIF(Rankings!$E:$E, $B14, Rankings!K:K) -> 2.195122 | D14: =AVERAGEIF(Rankings!$E:$E, $B14, Rankings!L:L) -> 4.037037 | E14: =AVERAGEIF(Rankings!$E:$E, $B14, Rankings!M:M) -> 4.4233129 | F14: =AVERAGEIF(Rankings!$E:$E, $B14, Rankings!N:N) -> 3.8383838 | G14: =AVERAGEIF(Rankings!$E:$E, $B14, Rankings!O:O) -> 4.402439 | H14: =AVERAGEIF(Rankings!$E:$E, $B14, Rankings!P:P) -> 4.1509434 | I14: =AVERAGEIF(Rankings!$E:$E, $B14, Rankings!R:R) -> 3.7777778 | J14: =AVERAGEIF(Rankings!$E:$E, $B14, Rankings!Q:Q) -> 4.0465116
B15: =Rankings!$L$1 -> Parker | C15: =AVERAGEIF(Rankings!$E:$E, $B15, Rankings!K:K) -> 3.7743902 | D15: =AVERAGEIF(Rankings!$E:$E, $B15, Rankings!L:L) -> 2.1165644 | E15: =AVERAGEIF(Rankings!$E:$E, $B15, Rankings!M:M) -> 3.2638037 | F15: =AVERAGEIF(Rankings!$E:$E, $B15, Rankings!N:N) -> 4.1212121 | G15: =AVERAGEIF(Rankings!$E:$E, $B15, Rankings!O:O) -> 3.7926829 | H15: =AVERAGEIF(Rankings!$E:$E, $B15, Rankings!P:P) -> 3.836478 | I15: =AVERAGEIF(Rankings!$E:$E, $B15, Rankings!R:R) -> 4.3777778 | J15: =AVERAGEIF(Rankings!$E:$E, $B15, Rankings!Q:Q) -> 4.2906977
B16: =Rankings!$M$1 -> Giacomo | C16: =AVERAGEIF(Rankings!$E:$E, $B16, Rankings!K:K) -> 3.8902439 | D16: =AVERAGEIF(Rankings!$E:$E, $B16, Rankings!L:L) -> 3.1851852 | E16: =AVERAGEIF(Rankings!$E:$E, $B16, Rankings!M:M) -> 1.7546012 | F16: =AVERAGEIF(Rankings!$E:$E, $B16, Rankings!N:N) -> 4.1818182 | G16: =AVERAGEIF(Rankings!$E:$E, $B16, Rankings!O:O) -> 4.1219512 | H16: =AVERAGEIF(Rankings!$E:$E, $B16, Rankings!P:P) -> 3.7484277 | I16: =AVERAGEIF(Rankings!$E:$E, $B16, Rankings!R:R) -> 4.4888889 | J16: =AVERAGEIF(Rankings!$E:$E, $B16, Rankings!Q:Q) -> 4.9883721
B17: =Rankings!$N$1 -> Rosey | C17: =AVERAGEIF(Rankings!$E:$E, $B17, Rankings!K:K) -> 3.5673077 | D17: =AVERAGEIF(Rankings!$E:$E, $B17, Rankings!L:L) -> 3.8653846 | E17: =AVERAGEIF(Rankings!$E:$E, $B17, Rankings!M:M) -> 4.1165049 | F17: =AVERAGEIF(Rankings!$E:$E, $B17, Rankings!N:N) -> 1.9191919 | G17: =AVERAGEIF(Rankings!$E:$E, $B17, Rankings!O:O) -> 3.8058252 | H17: =AVERAGEIF(Rankings!$E:$E, $B17, Rankings!P:P) -> 4.223301 | I17: =AVERAGEIF(Rankings!$E:$E, $B17, Rankings!R:R) -> 4 | J17: =AVERAGEIF(Rankings!$E:$E, $B17, Rankings!Q:Q) -> 3.9767442
B18: =Rankings!$O$1 -> TTAC | C18: =AVERAGEIF(Rankings!$E:$E, $B18, Rankings!K:K) -> 4.8719512 | D18: =AVERAGEIF(Rankings!$E:$E, $B18, Rankings!L:L) -> 4.9691358 | E18: =AVERAGEIF(Rankings!$E:$E, $B18, Rankings!M:M) -> 4.9141104 | F18: =AVERAGEIF(Rankings!$E:$E, $B18, Rankings!N:N) -> 5.3030303 | G18: =AVERAGEIF(Rankings!$E:$E, $B18, Rankings!O:O) -> 2.4756098 | H18: =AVERAGEIF(Rankings!$E:$E, $B18, Rankings!P:P) -> 4.5031447 | I18: =AVERAGEIF(Rankings!$E:$E, $B18, Rankings!R:R) -> 5.2888889 | J18: =AVERAGEIF(Rankings!$E:$E, $B18, Rankings!Q:Q) -> 3.7325581
B19: =Rankings!$P$1 -> Weston | C19: =AVERAGEIF(Rankings!$E:$E, $B19, Rankings!K:K) -> 3.8780488 | D19: =AVERAGEIF(Rankings!$E:$E, $B19, Rankings!L:L) -> 3.9753086 | E19: =AVERAGEIF(Rankings!$E:$E, $B19, Rankings!M:M) -> 3.6687117 | F19: =AVERAGEIF(Rankings!$E:$E, $B19, Rankings!N:N) -> 3.9494949 | G19: =AVERAGEIF(Rankings!$E:$E, $B19, Rankings!O:O) -> 4.1585366 | H19: =AVERAGEIF(Rankings!$E:$E, $B19, Rankings!P:P) -> 2.0440252 | I19: =AVERAGEIF(Rankings!$E:$E, $B19, Rankings!R:R) -> 3.4888889 | J19: =AVERAGEIF(Rankings!$E:$E, $B19, Rankings!Q:Q) -> 3.6976744
B20: =Rankings!$R$1 -> Jake | C20: =AVERAGEIF(Rankings!$E:$E, $B20, Rankings!K:K) -> 4.7346939 | D20: =AVERAGEIF(Rankings!$E:$E, $B20, Rankings!L:L) -> 4.7755102 | E20: =AVERAGEIF(Rankings!$E:$E, $B20, Rankings!M:M) -> 4.6938776 | F20: =AVERAGEIF(Rankings!$E:$E, $B20, Rankings!N:N) -> 4.2857143 | G20: =AVERAGEIF(Rankings!$E:$E, $B20, Rankings!O:O) -> 4.244898 | H20: =AVERAGEIF(Rankings!$E:$E, $B20, Rankings!P:P) -> 4.4081633 | I20: =AVERAGEIF(Rankings!$E:$E, $B20, Rankings!R:R) -> 2.5777778 | J20: N/A
B21: =Rankings!$Q$1 -> Flocco | C21: =AVERAGEIF(Rankings!$E:$E, $B21, Rankings!K:K) -> 3.8372093 | D21: =AVERAGEIF(Rankings!$E:$E, $B21, Rankings!L:L) -> 4.1627907 | E21: =AVERAGEIF(Rankings!$E:$E, $B21, Rankings!M:M) -> 4.3488372 | F21: =AVERAGEIF(Rankings!$E:$E, $B21, Rankings!N:N) -> 4.45 | G21: =AVERAGEIF(Rankings!$E:$E, $B21, Rankings!O:O) -> 3.1627907 | H21: =AVERAGEIF(Rankings!$E:$E, $B21, Rankings!P:P) -> 4.0348837 | I21: N/A | J21: =AVERAGEIF(Rankings!$E:$E, $B21, Rankings!Q:Q) -> 1.6823529
B23: Best Rank
B24: Poster/Voter | C24: =Rankings!$K$1 -> Logan | D24: =Rankings!$L$1 -> Parker | E24: =Rankings!$M$1 -> Giacomo | F24: =Rankings!$N$1 -> Rosey | G24: =Rankings!$O$1 -> TTAC | H24: =Rankings!$P$1 -> Weston | I24: =Rankings!$R$1 -> Jake | J24: =Rankings!$Q$1 -> Flocco
B25: =Rankings!$K$1 -> Logan | C25: =MINIFS(Rankings!K:K, Rankings!$E:$E, $B25) -> 1 | D25: =MINIFS(Rankings!L:L, Rankings!$E:$E, $B25) -> 1 | E25: =MINIFS(Rankings!M:M, Rankings!$E:$E, $B25) -> 1 | F25: =MINIFS(Rankings!N:N, Rankings!$E:$E, $B25) -> 1 | G25: =MINIFS(Rankings!O:O, Rankings!$E:$E, $B25) -> 1 | H25: =MINIFS(Rankings!P:P, Rankings!$E:$E, $B25) -> 1 | I25: =MINIFS(Rankings!R:R, Rankings!$E:$E, $B25) -> 1 | J25: =MINIFS(Rankings!Q:Q, Rankings!$E:$E, $B25) -> 1
B26: =Rankings!$L$1 -> Parker | C26: =MINIFS(Rankings!K:K, Rankings!$E:$E, $B26) -> 1 | D26: =MINIFS(Rankings!L:L, Rankings!$E:$E, $B26) -> 1 | E26: =MINIFS(Rankings!M:M, Rankings!$E:$E, $B26) -> 1 | F26: =MINIFS(Rankings!N:N, Rankings!$E:$E, $B26) -> 1 | G26: =MINIFS(Rankings!O:O, Rankings!$E:$E, $B26) -> 1 | H26: =MINIFS(Rankings!P:P, Rankings!$E:$E, $B26) -> 1 | I26: =MINIFS(Rankings!R:R, Rankings!$E:$E, $B26) -> 1 | J26: =MINIFS(Rankings!Q:Q, Rankings!$E:$E, $B26) -> 1
B27: =Rankings!$M$1 -> Giacomo | C27: =MINIFS(Rankings!K:K, Rankings!$E:$E, $B27) -> 1 | D27: =MINIFS(Rankings!L:L, Rankings!$E:$E, $B27) -> 1 | E27: =MINIFS(Rankings!M:M, Rankings!$E:$E, $B27) -> 1 | F27: =MINIFS(Rankings!N:N, Rankings!$E:$E, $B27) -> 1 | G27: =MINIFS(Rankings!O:O, Rankings!$E:$E, $B27) -> 1 | H27: =MINIFS(Rankings!P:P, Rankings!$E:$E, $B27) -> 1 | I27: =MINIFS(Rankings!R:R, Rankings!$E:$E, $B27) -> 1 | J27: =MINIFS(Rankings!Q:Q, Rankings!$E:$E, $B27) -> 1
B28: =Rankings!$N$1 -> Rosey | C28: =MINIFS(Rankings!K:K, Rankings!$E:$E, $B28) -> 1 | D28: =MINIFS(Rankings!L:L, Rankings!$E:$E, $B28) -> 1 | E28: =MINIFS(Rankings!M:M, Rankings!$E:$E, $B28) -> 1 | F28: =MINIFS(Rankings!N:N, Rankings!$E:$E, $B28) -> 1 | G28: =MINIFS(Rankings!O:O, Rankings!$E:$E, $B28) -> 1 | H28: =MINIFS(Rankings!P:P, Rankings!$E:$E, $B28) -> 1 | I28: =MINIFS(Rankings!R:R, Rankings!$E:$E, $B28) -> 1 | J28: =MINIFS(Rankings!Q:Q, Rankings!$E:$E, $B28) -> 1
B29: =Rankings!$O$1 -> TTAC | C29: =MINIFS(Rankings!K:K, Rankings!$E:$E, $B29) -> 1 | D29: =MINIFS(Rankings!L:L, Rankings!$E:$E, $B29) -> 1 | E29: =MINIFS(Rankings!M:M, Rankings!$E:$E, $B29) -> 1 | F29: =MINIFS(Rankings!N:N, Rankings!$E:$E, $B29) -> 1 | G29: =MINIFS(Rankings!O:O, Rankings!$E:$E, $B29) -> 1 | H29: =MINIFS(Rankings!P:P, Rankings!$E:$E, $B29) -> 1 | I29: =MINIFS(Rankings!R:R, Rankings!$E:$E, $B29) -> 1 | J29: =MINIFS(Rankings!Q:Q, Rankings!$E:$E, $B29) -> 1
B30: =Rankings!$P$1 -> Weston | C30: =MINIFS(Rankings!K:K, Rankings!$E:$E, $B30) -> 1 | D30: =MINIFS(Rankings!L:L, Rankings!$E:$E, $B30) -> 1 | E30: =MINIFS(Rankings!M:M, Rankings!$E:$E, $B30) -> 1 | F30: =MINIFS(Rankings!N:N, Rankings!$E:$E, $B30) -> 1 | G30: =MINIFS(Rankings!O:O, Rankings!$E:$E, $B30) -> 1 | H30: =MINIFS(Rankings!P:P, Rankings!$E:$E, $B30) -> 1 | I30: =MINIFS(Rankings!R:R, Rankings!$E:$E, $B30) -> 1 | J30: =MINIFS(Rankings!Q:Q, Rankings!$E:$E, $B30) -> 1
B31: =Rankings!$R$1 -> Jake | C31: =MINIFS(Rankings!K:K, Rankings!$E:$E, $B31) -> 1 | D31: =MINIFS(Rankings!L:L, Rankings!$E:$E, $B31) -> 1 | E31: =MINIFS(Rankings!M:M, Rankings!$E:$E, $B31) -> 1 | F31: =MINIFS(Rankings!N:N, Rankings!$E:$E, $B31) -> 1 | G31: =MINIFS(Rankings!O:O, Rankings!$E:$E, $B31) -> 1 | H31: =MINIFS(Rankings!P:P, Rankings!$E:$E, $B31) -> 1 | I31: =MINIFS(Rankings!R:R, Rankings!$E:$E, $B31) -> 1 | J31: N/A
B32: =Rankings!$Q$1 -> Flocco | C32: =MINIFS(Rankings!K:K, Rankings!$E:$E, $B32) -> 1 | D32: =MINIFS(Rankings!L:L, Rankings!$E:$E, $B32) -> 1 | E32: =MINIFS(Rankings!M:M, Rankings!$E:$E, $B32) -> 1 | F32: =MINIFS(Rankings!N:N, Rankings!$E:$E, $B32) -> 1 | G32: =MINIFS(Rankings!O:O, Rankings!$E:$E, $B32) -> 1 | H32: =MINIFS(Rankings!P:P, Rankings!$E:$E, $B32) -> 1 | I32: N/A | J32: =MINIFS(Rankings!Q:Q, Rankings!$E:$E, $B32) -> 1
B34: Worst Rank
B35: Poster/Voter | C35: =Rankings!$K$1 -> Logan | D35: =Rankings!$L$1 -> Parker | E35: =Rankings!$M$1 -> Giacomo | F35: =Rankings!$N$1 -> Rosey | G35: =Rankings!$O$1 -> TTAC | H35: =Rankings!$P$1 -> Weston | I35: =Rankings!$R$1 -> Jake | J35: =Rankings!$Q$1 -> Flocco
B36: =Rankings!$K$1 -> Logan | C36: =MAXIFS(Rankings!K:K, Rankings!$E:$E, $B36) -> 7 | D36: =MAXIFS(Rankings!L:L, Rankings!$E:$E, $B36) -> 7 | E36: =MAXIFS(Rankings!M:M, Rankings!$E:$E, $B36) -> 7 | F36: =MAXIFS(Rankings!N:N, Rankings!$E:$E, $B36) -> 7 | G36: =MAXIFS(Rankings!O:O, Rankings!$E:$E, $B36) -> 7 | H36: =MAXIFS(Rankings!P:P, Rankings!$E:$E, $B36) -> 7 | I36: =MAXIFS(Rankings!R:R, Rankings!$E:$E, $B36) -> 7 | J36: =MAXIFS(Rankings!Q:Q, Rankings!$E:$E, $B36) -> 7
B37: =Rankings!$L$1 -> Parker | C37: =MAXIFS(Rankings!K:K, Rankings!$E:$E, $B37) -> 7 | D37: =MAXIFS(Rankings!L:L, Rankings!$E:$E, $B37) -> 5 | E37: =MAXIFS(Rankings!M:M, Rankings!$E:$E, $B37) -> 7 | F37: =MAXIFS(Rankings!N:N, Rankings!$E:$E, $B37) -> 7 | G37: =MAXIFS(Rankings!O:O, Rankings!$E:$E, $B37) -> 7 | H37: =MAXIFS(Rankings!P:P, Rankings!$E:$E, $B37) -> 7 | I37: =MAXIFS(Rankings!R:R, Rankings!$E:$E, $B37) -> 7 | J37: =MAXIFS(Rankings!Q:Q, Rankings!$E:$E, $B37) -> 7
B38: =Rankings!$M$1 -> Giacomo | C38: =MAXIFS(Rankings!K:K, Rankings!$E:$E, $B38) -> 7 | D38: =MAXIFS(Rankings!L:L, Rankings!$E:$E, $B38) -> 7 | E38: =MAXIFS(Rankings!M:M, Rankings!$E:$E, $B38) -> 6 | F38: =MAXIFS(Rankings!N:N, Rankings!$E:$E, $B38) -> 7 | G38: =MAXIFS(Rankings!O:O, Rankings!$E:$E, $B38) -> 7 | H38: =MAXIFS(Rankings!P:P, Rankings!$E:$E, $B38) -> 7 | I38: =MAXIFS(Rankings!R:R, Rankings!$E:$E, $B38) -> 7 | J38: =MAXIFS(Rankings!Q:Q, Rankings!$E:$E, $B38) -> 7
B39: =Rankings!$N$1 -> Rosey | C39: =MAXIFS(Rankings!K:K, Rankings!$E:$E, $B39) -> 7 | D39: =MAXIFS(Rankings!L:L, Rankings!$E:$E, $B39) -> 7 | E39: =MAXIFS(Rankings!M:M, Rankings!$E:$E, $B39) -> 7 | F39: =MAXIFS(Rankings!N:N, Rankings!$E:$E, $B39) -> 6 | G39: =MAXIFS(Rankings!O:O, Rankings!$E:$E, $B39) -> 7 | H39: =MAXIFS(Rankings!P:P, Rankings!$E:$E, $B39) -> 7 | I39: =MAXIFS(Rankings!R:R, Rankings!$E:$E, $B39) -> 7 | J39: =MAXIFS(Rankings!Q:Q, Rankings!$E:$E, $B39) -> 7
B40: =Rankings!$O$1 -> TTAC | C40: =MAXIFS(Rankings!K:K, Rankings!$E:$E, $B40) -> 7 | D40: =MAXIFS(Rankings!L:L, Rankings!$E:$E, $B40) -> 7 | E40: =MAXIFS(Rankings!M:M, Rankings!$E:$E, $B40) -> 7 | F40: =MAXIFS(Rankings!N:N, Rankings!$E:$E, $B40) -> 7 | G40: =MAXIFS(Rankings!O:O, Rankings!$E:$E, $B40) -> 7 | H40: =MAXIFS(Rankings!P:P, Rankings!$E:$E, $B40) -> 7 | I40: =MAXIFS(Rankings!R:R, Rankings!$E:$E, $B40) -> 7 | J40: =MAXIFS(Rankings!Q:Q, Rankings!$E:$E, $B40) -> 7
B41: =Rankings!$P$1 -> Weston | C41: =MAXIFS(Rankings!K:K, Rankings!$E:$E, $B41) -> 7 | D41: =MAXIFS(Rankings!L:L, Rankings!$E:$E, $B41) -> 7 | E41: =MAXIFS(Rankings!M:M, Rankings!$E:$E, $B41) -> 7 | F41: =MAXIFS(Rankings!N:N, Rankings!$E:$E, $B41) -> 7 | G41: =MAXIFS(Rankings!O:O, Rankings!$E:$E, $B41) -> 7 | H41: =MAXIFS(Rankings!P:P, Rankings!$E:$E, $B41) -> 7 | I41: =MAXIFS(Rankings!R:R, Rankings!$E:$E, $B41) -> 7 | J41: =MAXIFS(Rankings!Q:Q, Rankings!$E:$E, $B41) -> 7
B42: =Rankings!$R$1 -> Jake | C42: =MAXIFS(Rankings!K:K, Rankings!$E:$E, $B42) -> 7 | D42: =MAXIFS(Rankings!L:L, Rankings!$E:$E, $B42) -> 7 | E42: =MAXIFS(Rankings!M:M, Rankings!$E:$E, $B42) -> 7 | F42: =MAXIFS(Rankings!N:N, Rankings!$E:$E, $B42) -> 7 | G42: =MAXIFS(Rankings!O:O, Rankings!$E:$E, $B42) -> 7 | H42: =MAXIFS(Rankings!P:P, Rankings!$E:$E, $B42) -> 7 | I42: =MAXIFS(Rankings!R:R, Rankings!$E:$E, $B42) -> 5 | J42: N/A
B43: =Rankings!$Q$1 -> Flocco | C43: =MAXIFS(Rankings!K:K, Rankings!$E:$E, $B43) -> 7 | D43: =MAXIFS(Rankings!L:L, Rankings!$E:$E, $B43) -> 7 | E43: =MAXIFS(Rankings!M:M, Rankings!$E:$E, $B43) -> 7 | F43: =MAXIFS(Rankings!N:N, Rankings!$E:$E, $B43) -> 7 | G43: =MAXIFS(Rankings!O:O, Rankings!$E:$E, $B43) -> 7 | H43: =MAXIFS(Rankings!P:P, Rankings!$E:$E, $B43) -> 7 | I43: N/A | J43: =MAXIFS(Rankings!Q:Q, Rankings!$E:$E, $B43) -> 7
B45: Hall of Fame | K45: Hall of Shame | S45: Hall of Same | AA45: Clown Award
...

Sheet Themes
B1: Up for Vote Themes | D1: Voters | K1: Results | M1: Poster | N1: Theme Pool | P1: Picked | Q1: Date | R1: Winning Song | S1: Winner
A2: Proponent | B2: Theme Suggestion | C2: Theme Description (Optional) | D2: Logan | E2: Parker | F2: Giacomo | G2: Rosey | H2: TTAC | I2: Weston | J2: Jake / Flocco | M2: =IFERROR(__xludf.DUMMYFUNCTION("FILTER($A:$C,$K:$K = ""Passed"")"),"Logan") -> Logan | N2: =IFERROR(__xludf.DUMMYFUNCTION("""COMPUTED_VALUE"""),"Bad Bitch Era") -> Bad Bitch Era | O2: =IFERROR(__xludf.DUMMYFUNCTION("""COMPUTED_VALUE"""),"A song that makes you feel like a bad bitch") -> A song that makes you feel like a bad bitch | P2: Yes | Q2: 46101 | R2: B.I.T.C.H. | S2: Rosey
A3: Logan | B3: Bad Bitch Era | C3: A song that makes you feel like a bad bitch | E3: In Favor | F3: In Favor | G3: In Favor | H3: In Favor | I3: In Favor | K3: =IF(COUNTIF(D3:J3, "Opposed") >=3,"Failed", IF(COUNTIF(D3:J3, "In Favor") >=4, "Passed", "")) -> Passed | M3: =IFERROR(__xludf.DUMMYFUNCTION("""COMPUTED_VALUE"""),"Parker") -> Parker | N3: =IFERROR(__xludf.DUMMYFUNCTION("""COMPUTED_VALUE"""),"Murdered/Murdered Someone") -> Murdered/Murdered Someone | P3: Yes | Q3: 46115 | R3: Perfect Ten | S3: Parker
A4: Parker | B4: Murdered/Murdered Someone | D4: In Favor | F4: In Favor | G4: In Favor | H4: In Favor | I4: In Favor | K4: =IF(COUNTIF(D4:J4, "Opposed") >=3,"Failed", IF(COUNTIF(D4:J4, "In Favor") >=4, "Passed", "")) -> Passed | M4: =IFERROR(__xludf.DUMMYFUNCTION("""COMPUTED_VALUE"""),"Giacomo") -> Giacomo | N4: =IFERROR(__xludf.DUMMYFUNCTION("""COMPUTED_VALUE"""),"Bechdel Test") -> Bechdel Test | O4: =IFERROR(__xludf.DUMMYFUNCTION("""COMPUTED_VALUE"""),"Has to pass it") -> Has to pass it | P4: Yes | Q4: 45933 | R4: All The Things She Said | S4: Rosey
A5: Giacomo | B5: Bechdel Test | C5: Has to pass it | D5: In Favor | E5: In Favor | F5: In Favor | G5: In Favor | H5: In Favor | I5: In Favor | J5: In Favor | K5: =IF(COUNTIF(D5:J5, "Opposed") >=3,"Failed", IF(COUNTIF(D5:J5, "In Favor") >=4, "Passed", "")) -> Passed | M5: =IFERROR(__xludf.DUMMYFUNCTION("""COMPUTED_VALUE"""),"Rosey") -> Rosey | N5: =IFERROR(__xludf.DUMMYFUNCTION("""COMPUTED_VALUE"""),"Sad Boy Hours") -> Sad Boy Hours | P5: Yes | Q5: 46073 | R5: Y LLORO | S5: Parker
A6: Rosey | B6: Sad Boy Hours | D6: In Favor | E6: In Favor | F6: In Favor | H6: In Favor | I6: In Favor | K6: =IF(COUNTIF(D6:J6, "Opposed") >=3,"Failed", IF(COUNTIF(D6:J6, "In Favor") >=4, "Passed", "")) -> Passed | M6: =IFERROR(__xludf.DUMMYFUNCTION("""COMPUTED_VALUE"""),"TTAC") -> TTAC | N6: =IFERROR(__xludf.DUMMYFUNCTION("""COMPUTED_VALUE"""),"Music Videos") -> Music Videos | O6: =IFERROR(__xludf.DUMMYFUNCTION("""COMPUTED_VALUE"""),"The music vid can take apart as the score or as separate, but it has to atleast be a song where the video adds to the experience or is iconic in one way or another ") -> The music vid can take apart as the score or as separate, but it has to atleast be a song where the video adds to the experience or is iconic in one way or another
A7: TTAC | B7: Music Videos | C7: The music vid can take apart as the score or as separate, but it has to atleast be a song where the video adds to the experience or is iconic in one way or another | D7: In Favor | E7: In Favor | F7: In Favor | G7: In Favor | I7: In Favor | K7: =IF(COUNTIF(D7:J7, "Opposed") >=3,"Failed", IF(COUNTIF(D7:J7, "In Favor") >=4, "Passed", "")) -> Passed | M7: =IFERROR(__xludf.DUMMYFUNCTION("""COMPUTED_VALUE"""),"Weston") -> Weston | N7: =IFERROR(__xludf.DUMMYFUNCTION("""COMPUTED_VALUE"""),"Quickscope montage") -> Quickscope montage | O7: =IFERROR(__xludf.DUMMYFUNCTION("""COMPUTED_VALUE"""),"Any song from a cod/cs/val edit") -> Any song from a cod/cs/val edit
A8: Weston | B8: Quickscope montage | C8: Any song from a cod/cs/val edit | D8: In Favor | E8: In Favor | F8: Opposed | G8: In Favor | H8: In Favor | J8: Opposed | K8: =IF(COUNTIF(D8:J8, "Opposed") >=3,"Failed", IF(COUNTIF(D8:J8, "In Favor") >=4, "Passed", "")) -> Passed | M8: =IFERROR(__xludf.DUMMYFUNCTION("""COMPUTED_VALUE"""),"Jake") -> Jake | N8: =IFERROR(__xludf.DUMMYFUNCTION("""COMPUTED_VALUE"""),"Famous Song in a Movie") -> Famous Song in a Movie | P8: Yes | Q8: 46059 | R8: I2I | S8: Weston
A9: Jake | B9: Famous Song in a Movie | D9: In Favor | E9: In Favor | F9: Opposed | G9: In Favor | H9: In Favor | I9: In Favor | J9: In Favor | K9: =IF(COUNTIF(D9:J9, "Opposed") >=3,"Failed", IF(COUNTIF(D9:J9, "In Favor") >=4, "Passed", "")) -> Passed | M9: =IFERROR(__xludf.DUMMYFUNCTION("""COMPUTED_VALUE"""),"Giacomo") -> Giacomo | N9: =IFERROR(__xludf.DUMMYFUNCTION("""COMPUTED_VALUE"""),"Horny") -> Horny | O9: =IFERROR(__xludf.DUMMYFUNCTION("""COMPUTED_VALUE"""),"Some freaky ahh shit that gon make you act up") -> Some freaky ahh shit that gon make you act up
A10: Logan | B10: Speed Round | C10: Song that's less than 1 minute | E10: Opposed | F10: Opposed | G10: Opposed | H10: In Favor | I10: In Favor | J10: In Favor | K10: =IF(COUNTIF(D10:J10, "Opposed") >=3,"Failed", IF(COUNTIF(D10:J10, "In Favor") >=4, "Passed", "")) -> Failed | M10: =IFERROR(__xludf.DUMMYFUNCTION("""COMPUTED_VALUE"""),"Rosey") -> Rosey | N10: =IFERROR(__xludf.DUMMYFUNCTION("""COMPUTED_VALUE"""),"XXL Freshman") -> XXL Freshman | P10: Yes | Q10: 46003 | R10: RNP | S10: Rosey
A11: Giacomo | B11: Horny | C11: Some freaky ahh shit that gon make you act up | D11: In Favor | E11: In Favor | H11: In Favor | I11: In Favor | J11: In Favor | K11: =IF(COUNTIF(D11:J11, "Opposed") >=3,"Failed", IF(COUNTIF(D11:J11, "In Favor") >=4, "Passed", "")) -> Passed | M11: =IFERROR(__xludf.DUMMYFUNCTION("""COMPUTED_VALUE"""),"TTAC") -> TTAC | N11: =IFERROR(__xludf.DUMMYFUNCTION("""COMPUTED_VALUE"""),"X-Mas Songs") -> X-Mas Songs | O11: =IFERROR(__xludf.DUMMYFUNCTION("""COMPUTED_VALUE"""),"Sometime in DEC") -> Sometime in DEC | P11: Yes | Q11: 46015 | R11: Last Christmas | S11: Rosey
A12: Rosey | B12: XXL Freshman | D12: In Favor | E12: In Favor | F12: In Favor | H12: In Favor | I12: In Favor | J12: In Favor | K12: =IF(COUNTIF(D12:J12, "Opposed") >=3,"Failed", IF(COUNTIF(D12:J12, "In Favor") >=4, "Passed", "")) -> Passed | M12: =IFERROR(__xludf.DUMMYFUNCTION("""COMPUTED_VALUE"""),"Jake") -> Jake | N12: =IFERROR(__xludf.DUMMYFUNCTION("""COMPUTED_VALUE"""),"Spooky/Scary Songs") -> Spooky/Scary Songs | P12: Yes | Q12: 45961 | R12: Lavender Town | S12: Logan
A13: TTAC | B13: X-Mas Songs | C13: Sometime in DEC | D13: In Favor | E13: In Favor | F13: In Favor | H13: In Favor | I13: In Favor | J13: Opposed | K13: =IF(COUNTIF(D13:J13, "Opposed") >=3,"Failed", IF(COUNTIF(D13:J13, "In Favor") >=4, "Passed", "")) -> Passed | M13: =IFERROR(__xludf.DUMMYFUNCTION("""COMPUTED_VALUE"""),"Logan") -> Logan | N13: =IFERROR(__xludf.DUMMYFUNCTION("""COMPUTED_VALUE"""),"Receiptify Top Artist") -> Receiptify Top Artist | O13: =IFERROR(__xludf.DUMMYFUNCTION("""COMPUTED_VALUE"""),"https://receiptify.herokuapp.com - Use this link to see your Top Artist at the time - 6 Months") -> https://receiptify.herokuapp.com - Use this link to see your Top Artist at the time - 6 Months
A14: Weston | B14: 27 club | C14: died at 27 years old | D14: In Favor | E14: Opposed | F14: Opposed | G14: Opposed | H14: In Favor | J14: In Favor | K14: =IF(COUNTIF(D14:J14, "Opposed") >=3,"Failed", IF(COUNTIF(D14:J14, "In Favor") >=4, "Passed", "")) -> Failed | M14: =IFERROR(__xludf.DUMMYFUNCTION("""COMPUTED_VALUE"""),"Giacomo") -> Giacomo | N14: =IFERROR(__xludf.DUMMYFUNCTION("""COMPUTED_VALUE"""),"Wrapped Song") -> Wrapped Song | O14: =IFERROR(__xludf.DUMMYFUNCTION("""COMPUTED_VALUE"""),"Pick a top 5 song from any of your wrapped") -> Pick a top 5 song from any of your wrapped
A15: Jake | B15: Spooky/Scary Songs | D15: In Favor | E15: In Favor | F15: In Favor | G15: In Favor | H15: In Favor | I15: In Favor | K15: =IF(COUNTIF(D15:J15, "Opposed") >=3,"Failed", IF(COUNTIF(D15:J15, "In Favor") >=4, "Passed", "")) -> Passed | M15: =IFERROR(__xludf.DUMMYFUNCTION("""COMPUTED_VALUE"""),"TTAC") -> TTAC | N15: =IFERROR(__xludf.DUMMYFUNCTION("""COMPUTED_VALUE"""),"Video Game OST") -> Video Game OST | P15: Yes | Q15: 45947 | R15: Unshaken | S15: Parker
A16: Logan | B16: Receiptify Top Artist | C16: https://receiptify.herokuapp.com - Use this link to see your Top Artist at the time - 6 Months | E16: In Favor | F16: Opposed | G16: In Favor | H16: In Favor | I16: In Favor | K16: =IF(COUNTIF(D16:J16, "Opposed") >=3,"Failed", IF(COUNTIF(D16:J16, "In Favor") >=4, "Passed", "")) -> Passed | M16: =IFERROR(__xludf.DUMMYFUNCTION("""COMPUTED_VALUE"""),"Weston") -> Weston | N16: =IFERROR(__xludf.DUMMYFUNCTION("""COMPUTED_VALUE"""),"Haters") -> Haters | O16: =IFERROR(__xludf.DUMMYFUNCTION("""COMPUTED_VALUE"""),"Diss tracks or songs that were made to spite someone/something") -> Diss tracks or songs that were made to spite someone/something | P16: Yes | Q16: 45975 | R16: HISS | S16: Logan
A17: Giacomo | B17: Wrapped Song | C17: Pick a top 5 song from any of your wrapped | D17: In Favor | E17: In Favor | G17: In Favor | H17: In Favor | I17: In Favor | K17: =IF(COUNTIF(D17:J17, "Opposed") >=3,"Failed", IF(COUNTIF(D17:J17, "In Favor") >=4, "Passed", "")) -> Passed | M17: =IFERROR(__xludf.DUMMYFUNCTION("""COMPUTED_VALUE"""),"Jake") -> Jake | N17: =IFERROR(__xludf.DUMMYFUNCTION("""COMPUTED_VALUE"""),"Secret Missions") -> Secret Missions | O17: =IFERROR(__xludf.DUMMYFUNCTION("""COMPUTED_VALUE"""),"Each person is assigned another theme at random and in secret and you have to pick a song for your secret theme. People can also guess at what other peoples secret theme was. ") -> Each person is assigned another theme at random and in secret and you have to pick a song for your secret theme. People can also guess at what other peoples secret theme was.
A18: TTAC | B18: Video Game OST | D18: In Favor | E18: In Favor | F18: Opposed | G18: In Favor | H18: In Favor | I18: In Favor | J18: In Favor | K18: =IF(COUNTIF(D18:J18, "Opposed") >=3,"Failed", IF(COUNTIF(D18:J18, "In Favor") >=4, "Passed", "")) -> Passed | M18: =IFERROR(__xludf.DUMMYFUNCTION("""COMPUTED_VALUE"""),"Logan") -> Logan | N18: =IFERROR(__xludf.DUMMYFUNCTION("""COMPUTED_VALUE"""),"Guilty Pleasure") -> Guilty Pleasure | O18: =IFERROR(__xludf.DUMMYFUNCTION("""COMPUTED_VALUE"""),"A song you are embaressed to like") -> A song you are embaressed to like | P18: Yes | Q18: 46241 | R18: Agora Hills | S18: Parker
A19: Weston | B19: Haters | C19: Diss tracks or songs that were made to spite someone/something | D19: In Favor | E19: In Favor | F19: In Favor | H19: In Favor | K19: =IF(COUNTIF(D19:J19, "Opposed") >=3,"Failed", IF(COUNTIF(D19:J19, "In Favor") >=4, "Passed", "")) -> Passed | M19: =IFERROR(__xludf.DUMMYFUNCTION("""COMPUTED_VALUE"""),"Giacomo") -> Giacomo | N19: =IFERROR(__xludf.DUMMYFUNCTION("""COMPUTED_VALUE"""),"The Ink Master") -> The Ink Master | O19: =IFERROR(__xludf.DUMMYFUNCTION("""COMPUTED_VALUE"""),"The winner of the flash challenge (last theme) has the power to assign the skulls (genre or topic) in the elimination tattoo (this theme)") -> The winner of the flash challenge (last theme) has the power to assign the skulls (genre or topic) in the elimination tattoo (this theme) | P19: Yes | Q19: 46045 | R19: Time | S19: Rosey
A20: Jake | B20: Secret Missions | C20: Each person is assigned another theme at random and in secret and you have to pick a song for your secret theme. People can also guess at what other peoples secret theme was. | D20: In Favor | E20: In Favor | F20: Opposed | H20: In Favor | I20: In Favor | K20: =IF(COUNTIF(D20:J20, "Opposed") >=3,"Failed", IF(COUNTIF(D20:J20, "In Favor") >=4, "Passed", "")) -> Passed | M20: =IFERROR(__xludf.DUMMYFUNCTION("""COMPUTED_VALUE"""),"Weston") -> Weston | N20: =IFERROR(__xludf.DUMMYFUNCTION("""COMPUTED_VALUE"""),"Local") -> Local | O20: =IFERROR(__xludf.DUMMYFUNCTION("""COMPUTED_VALUE"""),"Any Artist/band from NJ or Philly") -> Any Artist/band from NJ or Philly | P20: Yes | Q20: 45989 | R20: The Seed (2.0) | S20: Rosey
A21: Logan | B21: Guilty Pleasure | C21: A song you are embaressed to like | E21: In Favor | F21: In Favor | G21: In Favor | H21: In Favor | I21: In Favor | K21: =IF(COUNTIF(D21:J21, "Opposed") >=3,"Failed", IF(COUNTIF(D21:J21, "In Favor") >=4, "Passed", "")) -> Passed | M21: =IFERROR(__xludf.DUMMYFUNCTION("""COMPUTED_VALUE"""),"Jake") -> Jake | N21: =IFERROR(__xludf.DUMMYFUNCTION("""COMPUTED_VALUE"""),"Weeb Song") -> Weeb Song | O21: =IFERROR(__xludf.DUMMYFUNCTION("""COMPUTED_VALUE"""),"A Japanese song, doesn't need to be anime related") -> A Japanese song, doesn't need to be anime related | P21: Yes | Q21: 46255
A22: Giacomo | B22: The Ink Master | C22: The winner of the flash challenge (last theme) has the power to assign the skulls (genre or topic) in the elimination tattoo (this theme) | D22: In Favor | E22: In Favor | H22: In Favor | I22: In Favor | K22: =IF(COUNTIF(D22:J22, "Opposed") >=3,"Failed", IF(COUNTIF(D22:J22, "In Favor") >=4, "Passed", "")) -> Passed | M22: =IFERROR(__xludf.DUMMYFUNCTION("""COMPUTED_VALUE"""),"Logan") -> Logan | N22: =IFERROR(__xludf.DUMMYFUNCTION("""COMPUTED_VALUE"""),"Instruments only") -> Instruments only | O22: =IFERROR(__xludf.DUMMYFUNCTION("""COMPUTED_VALUE"""),"No EDM") -> No EDM | P22: Yes | Q22: 46199 | R22: Face My Fears | S22: Weston
A23: TTAC | B23: Genre Medley | C23: Everyone is assigned a person and they have to pick a genre of music for that person to oblige by | D23: Opposed | E23: Opposed | F23: In Favor | G23: Opposed | H23: In Favor | I23: Opposed | K23: =IF(COUNTIF(D23:J23, "Opposed") >=3,"Failed", IF(COUNTIF(D23:J23, "In Favor") >=4, "Passed", "")) -> Failed | M23: =IFERROR(__xludf.DUMMYFUNCTION("""COMPUTED_VALUE"""),"Weston") -> Weston | N23: =IFERROR(__xludf.DUMMYFUNCTION("""COMPUTED_VALUE"""),"Beat Switch") -> Beat Switch | O23: =IFERROR(__xludf.DUMMYFUNCTION("""COMPUTED_VALUE"""),"Songs with a beat switch in there") -> Songs with a beat switch in there
A24: Weston | B24: Local | C24: Any Artist/band from NJ or Philly | D24: In Favor | E24: In Favor | F24: In Favor | H24: In Favor | K24: =IF(COUNTIF(D24:J24, "Opposed") >=3,"Failed", IF(COUNTIF(D24:J24, "In Favor") >=4, "Passed", "")) -> Passed | M24: =IFERROR(__xludf.DUMMYFUNCTION("""COMPUTED_VALUE"""),"Jake") -> Jake | N24: =IFERROR(__xludf.DUMMYFUNCTION("""COMPUTED_VALUE"""),"Songs that make you want to drive 100 mph") -> Songs that make you want to drive 100 mph | O24: =IFERROR(__xludf.DUMMYFUNCTION("""COMPUTED_VALUE"""),"These are songs that make you wanna go fast!") -> These are songs that make you wanna go fast! | P24: Yes | Q24: 46213 | R24: COWBELL WARRIORS! | S24: Logan
